Traceback (most recent call last):
  File "C:\Users\malik\AppData\Local\Packages\PythonSoftwareFoundation.Python.3.11_qbz5n2kfra8p0\LocalCache\local-packages\Python311\site-packages\jupyter_cache\executors\utils.py", line 58, in single_nb_execution
    executenb(
  File "C:\Users\malik\AppData\Local\Packages\PythonSoftwareFoundation.Python.3.11_qbz5n2kfra8p0\LocalCache\local-packages\Python311\site-packages\nbclient\client.py", line 1314, in execute
    return NotebookClient(nb=nb, resources=resources, km=km, **kwargs).execute()
           ^^^^^^^^^^^^^^^^^^^^^^^^^^^^^^^^^^^^^^^^^^^^^^^^^^^^^^^^^^^^^^^^^^^^^
  File "C:\Users\malik\AppData\Local\Packages\PythonSoftwareFoundation.Python.3.11_qbz5n2kfra8p0\LocalCache\local-packages\Python311\site-packages\jupyter_core\utils\__init__.py", line 165, in wrapped
    return loop.run_until_complete(inner)
           ^^^^^^^^^^^^^^^^^^^^^^^^^^^^^^
  File "C:\Program Files\WindowsApps\PythonSoftwareFoundation.Python.3.11_3.11.2544.0_x64__qbz5n2kfra8p0\Lib\asyncio\base_events.py", line 654, in run_until_complete
    return future.result()
           ^^^^^^^^^^^^^^^
  File "C:\Users\malik\AppData\Local\Packages\PythonSoftwareFoundation.Python.3.11_qbz5n2kfra8p0\LocalCache\local-packages\Python311\site-packages\nbclient\client.py", line 709, in async_execute
    await self.async_execute_cell(
  File "C:\Users\malik\AppData\Local\Packages\PythonSoftwareFoundation.Python.3.11_qbz5n2kfra8p0\LocalCache\local-packages\Python311\site-packages\nbclient\client.py", line 1062, in async_execute_cell
    await self._check_raise_for_error(cell, cell_index, exec_reply)
  File "C:\Users\malik\AppData\Local\Packages\PythonSoftwareFoundation.Python.3.11_qbz5n2kfra8p0\LocalCache\local-packages\Python311\site-packages\nbclient\client.py", line 918, in _check_raise_for_error
    raise CellExecutionError.from_cell_and_msg(cell, exec_reply_content)
nbclient.exceptions.CellExecutionError: An error occurred while executing the following cell:
------------------
# prompt: solve 4 * np.exp(0.8 * x) - 0.5 * y with scipy , step size 2 and output the error

import numpy as np
from scipy.integrate import solve_ivp

def f(x, y):
  """The differential equation."""
  return 4 * np.exp(0.8 * x) - 0.5 * y

# Initial conditions
x0 = 0
y0 = 2
x_end = 2

# Solve the differential equation using solve_ivp
sol = solve_ivp(f, (x0, x_end), [y0], method='RK45')
print(sol)


# Extract the solution
y_numerical = sol.y[0][-1]

# Analytical solution (you might need to calculate this beforehand)
y_analytical = 14.84392

# Calculate the error
error = abs(y_numerical - y_analytical)

print(f"Numerical solution: {y_numerical}")
print(f"Error: {error}")
------------------


[1;31m---------------------------------------------------------------------------[0m
[1;31mModuleNotFoundError[0m                       Traceback (most recent call last)
Cell [1;32mIn[4], line 4[0m
[0;32m      1[0m [38;5;66;03m# prompt: solve 4 * np.exp(0.8 * x) - 0.5 * y with scipy , step size 2 and output the error[39;00m
[0;32m      3[0m [38;5;28;01mimport[39;00m [38;5;21;01mnumpy[39;00m [38;5;28;01mas[39;00m [38;5;21;01mnp[39;00m
[1;32m----> 4[0m [38;5;28;01mfrom[39;00m [38;5;21;01mscipy[39;00m[38;5;21;01m.[39;00m[38;5;21;01mintegrate[39;00m [38;5;28;01mimport[39;00m solve_ivp
[0;32m      6[0m [38;5;28;01mdef[39;00m [38;5;21mf[39m(x, y):
[0;32m      7[0m [38;5;250m  [39m[38;5;124;03m"""The differential equation."""[39;00m

[1;31mModuleNotFoundError[0m: No module named 'scipy'

