Traceback (most recent call last):
  File "C:\Users\malik\AppData\Local\Programs\Python\Python313\Lib\site-packages\jupyter_cache\executors\utils.py", line 58, in single_nb_execution
    executenb(
    ~~~~~~~~~^
        nb,
        ^^^
    ...<4 lines>...
        **kwargs,
        ^^^^^^^^^
    )
    ^
  File "C:\Users\malik\AppData\Local\Programs\Python\Python313\Lib\site-packages\nbclient\client.py", line 1314, in execute
    return NotebookClient(nb=nb, resources=resources, km=km, **kwargs).execute()
           ~~~~~~~~~~~~~~~~~~~~~~~~~~~~~~~~~~~~~~~~~~~~~~~~~~~~~~~~~~~~~~~~~~~^^
  File "C:\Users\malik\AppData\Local\Programs\Python\Python313\Lib\site-packages\jupyter_core\utils\__init__.py", line 165, in wrapped
    return loop.run_until_complete(inner)
           ~~~~~~~~~~~~~~~~~~~~~~~^^^^^^^
  File "C:\Users\malik\AppData\Local\Programs\Python\Python313\Lib\asyncio\base_events.py", line 721, in run_until_complete
    return future.result()
           ~~~~~~~~~~~~~^^
  File "C:\Users\malik\AppData\Local\Programs\Python\Python313\Lib\site-packages\nbclient\client.py", line 709, in async_execute
    await self.async_execute_cell(
        cell, index, execution_count=self.code_cells_executed + 1
    )
  File "C:\Users\malik\AppData\Local\Programs\Python\Python313\Lib\site-packages\nbclient\client.py", line 1062, in async_execute_cell
    await self._check_raise_for_error(cell, cell_index, exec_reply)
  File "C:\Users\malik\AppData\Local\Programs\Python\Python313\Lib\site-packages\nbclient\client.py", line 918, in _check_raise_for_error
    raise CellExecutionError.from_cell_and_msg(cell, exec_reply_content)
nbclient.exceptions.CellExecutionError: An error occurred while executing the following cell:
------------------
def time_matmult(n):
  import numpy as np
  A = np.random.rand(n, n)
  B = np.random.rand(n, n)
  %timeit C = A @ B

time_matmult(100)
time_matmult(1000)
time_matmult(2000)
time_matmult(4000)
------------------


[1;31m---------------------------------------------------------------------------[0m
[1;31mModuleNotFoundError[0m                       Traceback (most recent call last)
Cell [1;32mIn[1], line 7[0m
[0;32m      4[0m   B [38;5;241m=[39m np[38;5;241m.[39mrandom[38;5;241m.[39mrand(n, n)
[0;32m      5[0m   get_ipython()[38;5;241m.[39mrun_line_magic([38;5;124m'[39m[38;5;124mtimeit[39m[38;5;124m'[39m, [38;5;124m'[39m[38;5;124mC = A @ B[39m[38;5;124m'[39m)
[1;32m----> 7[0m [43mtime_matmult[49m[43m([49m[38;5;241;43m100[39;49m[43m)[49m
[0;32m      8[0m time_matmult([38;5;241m1000[39m)
[0;32m      9[0m time_matmult([38;5;241m2000[39m)

Cell [1;32mIn[1], line 2[0m, in [0;36mtime_matmult[1;34m(n)[0m
[0;32m      1[0m [38;5;28;01mdef[39;00m [38;5;21mtime_matmult[39m(n):
[1;32m----> 2[0m   [38;5;28;01mimport[39;00m [38;5;21;01mnumpy[39;00m [38;5;28;01mas[39;00m [38;5;21;01mnp[39;00m
[0;32m      3[0m   A [38;5;241m=[39m np[38;5;241m.[39mrandom[38;5;241m.[39mrand(n, n)
[0;32m      4[0m   B [38;5;241m=[39m np[38;5;241m.[39mrandom[38;5;241m.[39mrand(n, n)

[1;31mModuleNotFoundError[0m: No module named 'numpy'

