Traceback (most recent call last):
  File "C:\Users\malik\AppData\Local\Packages\PythonSoftwareFoundation.Python.3.11_qbz5n2kfra8p0\LocalCache\local-packages\Python311\site-packages\jupyter_cache\executors\utils.py", line 58, in single_nb_execution
    executenb(
  File "C:\Users\malik\AppData\Local\Packages\PythonSoftwareFoundation.Python.3.11_qbz5n2kfra8p0\LocalCache\local-packages\Python311\site-packages\nbclient\client.py", line 1314, in execute
    return NotebookClient(nb=nb, resources=resources, km=km, **kwargs).execute()
           ^^^^^^^^^^^^^^^^^^^^^^^^^^^^^^^^^^^^^^^^^^^^^^^^^^^^^^^^^^^^^^^^^^^^^
  File "C:\Users\malik\AppData\Local\Packages\PythonSoftwareFoundation.Python.3.11_qbz5n2kfra8p0\LocalCache\local-packages\Python311\site-packages\jupyter_core\utils\__init__.py", line 165, in wrapped
    return loop.run_until_complete(inner)
           ^^^^^^^^^^^^^^^^^^^^^^^^^^^^^^
  File "C:\Program Files\WindowsApps\PythonSoftwareFoundation.Python.3.11_3.11.2544.0_x64__qbz5n2kfra8p0\Lib\asyncio\base_events.py", line 654, in run_until_complete
    return future.result()
           ^^^^^^^^^^^^^^^
  File "C:\Users\malik\AppData\Local\Packages\PythonSoftwareFoundation.Python.3.11_qbz5n2kfra8p0\LocalCache\local-packages\Python311\site-packages\nbclient\client.py", line 709, in async_execute
    await self.async_execute_cell(
  File "C:\Users\malik\AppData\Local\Packages\PythonSoftwareFoundation.Python.3.11_qbz5n2kfra8p0\LocalCache\local-packages\Python311\site-packages\nbclient\client.py", line 1062, in async_execute_cell
    await self._check_raise_for_error(cell, cell_index, exec_reply)
  File "C:\Users\malik\AppData\Local\Packages\PythonSoftwareFoundation.Python.3.11_qbz5n2kfra8p0\LocalCache\local-packages\Python311\site-packages\nbclient\client.py", line 918, in _check_raise_for_error
    raise CellExecutionError.from_cell_and_msg(cell, exec_reply_content)
nbclient.exceptions.CellExecutionError: An error occurred while executing the following cell:
------------------
# prompt: Define a function that takes a function, plots it with xrange -10 to 10 and y range -10 to 10 with a line, solves for the roots using fsolve if the roots were found, plot them with dots
# NB: Modified from original output

import numpy as np
import matplotlib.pyplot as plt
from scipy.optimize import root

def plot_and_find_roots(func):
  """Plots a function and finds its roots using fsolve.

  Args:
    func: The function to plot and find roots for.
  """

  x = np.linspace(-10, 10, 400)
  y = func(x)

  plt.figure(figsize=(8, 6))
  plt.plot(x, y, label='f(x)')
  plt.axhline(y=0, color='black', linestyle='--')  # Plot the x-axis
  plt.xlabel('x')
  plt.ylabel('f(x)')
  plt.title('Plot of f(x) and its Roots')
  plt.xlim([-10, 10])
  plt.ylim([-10, 10])

  x0s = np.arange(-10,10,1)
  for x0 in x0s:
    r = root(func, x0=x0)
    if r.success:
      plt.plot(r.x, r.fun, 'ro', markersize=8)  # Plot root with a red dot
    plt.legend(['f(x)', 'Roots'])

  plt.grid(True)
  plt.show()
------------------


[1;31m---------------------------------------------------------------------------[0m
[1;31mModuleNotFoundError[0m                       Traceback (most recent call last)
Cell [1;32mIn[1], line 6[0m
[0;32m      4[0m [38;5;28;01mimport[39;00m [38;5;21;01mnumpy[39;00m [38;5;28;01mas[39;00m [38;5;21;01mnp[39;00m
[0;32m      5[0m [38;5;28;01mimport[39;00m [38;5;21;01mmatplotlib[39;00m[38;5;21;01m.[39;00m[38;5;21;01mpyplot[39;00m [38;5;28;01mas[39;00m [38;5;21;01mplt[39;00m
[1;32m----> 6[0m [38;5;28;01mfrom[39;00m [38;5;21;01mscipy[39;00m[38;5;21;01m.[39;00m[38;5;21;01moptimize[39;00m [38;5;28;01mimport[39;00m root
[0;32m      8[0m [38;5;28;01mdef[39;00m [38;5;21mplot_and_find_roots[39m(func):
[0;32m      9[0m [38;5;250m  [39m[38;5;124;03m"""Plots a function and finds its roots using fsolve.[39;00m
[0;32m     10[0m 
[0;32m     11[0m [38;5;124;03m  Args:[39;00m
[0;32m     12[0m [38;5;124;03m    func: The function to plot and find roots for.[39;00m
[0;32m     13[0m [38;5;124;03m  """[39;00m

[1;31mModuleNotFoundError[0m: No module named 'scipy'

